Traceback (most recent call last):
  File "/home/abresh/anaconda3/envs/airflow-environment/lib/python3.9/site-packages/psutil/_pslinux.py", line 1643, in wrapper
    return fun(self, *args, **kwargs)
  File "/home/abresh/anaconda3/envs/airflow-environment/lib/python3.9/site-packages/psutil/_common.py", line 486, in wrapper
    raise raise_from(err, None)
  File "<string>", line 3, in raise_from
  File "/home/abresh/anaconda3/envs/airflow-environment/lib/python3.9/site-packages/psutil/_common.py", line 484, in wrapper
    return fun(self)
  File "/home/abresh/anaconda3/envs/airflow-environment/lib/python3.9/site-packages/psutil/_pslinux.py", line 1705, in _parse_stat_file
    data = bcat("%s/%s/stat" % (self._procfs_path, self.pid))
  File "/home/abresh/anaconda3/envs/airflow-environment/lib/python3.9/site-packages/psutil/_common.py", line 820, in bcat
    return cat(fname, fallback=fallback, _open=open_binary)
  File "/home/abresh/anaconda3/envs/airflow-environment/lib/python3.9/site-packages/psutil/_common.py", line 808, in cat
    with _open(fname) as f:
  File "/home/abresh/anaconda3/envs/airflow-environment/lib/python3.9/site-packages/psutil/_common.py", line 772, in open_binary
    return open(fname, "rb", buffering=FILE_READ_BUFFER_SIZE)
FileNotFoundError: [Errno 2] No such file or directory: '/proc/49796/stat'

During handling of the above exception, another exception occurred:

Traceback (most recent call last):
  File "/home/abresh/anaconda3/envs/airflow-environment/lib/python3.9/site-packages/psutil/__init__.py", line 350, in _init
    self.create_time()
  File "/home/abresh/anaconda3/envs/airflow-environment/lib/python3.9/site-packages/psutil/__init__.py", line 735, in create_time
    self._create_time = self._proc.create_time()
  File "/home/abresh/anaconda3/envs/airflow-environment/lib/python3.9/site-packages/psutil/_pslinux.py", line 1643, in wrapper
    return fun(self, *args, **kwargs)
  File "/home/abresh/anaconda3/envs/airflow-environment/lib/python3.9/site-packages/psutil/_pslinux.py", line 1870, in create_time
    ctime = float(self._parse_stat_file()['create_time'])
  File "/home/abresh/anaconda3/envs/airflow-environment/lib/python3.9/site-packages/psutil/_pslinux.py", line 1652, in wrapper
    raise NoSuchProcess(self.pid, self._name)
psutil.NoSuchProcess: process no longer exists (pid=49796)

During handling of the above exception, another exception occurred:

Traceback (most recent call last):
  File "/home/abresh/anaconda3/envs/airflow-environment/bin/airflow", line 8, in <module>
    sys.exit(main())
  File "/home/abresh/anaconda3/envs/airflow-environment/lib/python3.9/site-packages/airflow/__main__.py", line 57, in main
    args.func(args)
  File "/home/abresh/anaconda3/envs/airflow-environment/lib/python3.9/site-packages/airflow/cli/cli_config.py", line 49, in command
    return func(*args, **kwargs)
  File "/home/abresh/anaconda3/envs/airflow-environment/lib/python3.9/site-packages/airflow/utils/cli.py", line 114, in wrapper
    return f(*args, **kwargs)
  File "/home/abresh/anaconda3/envs/airflow-environment/lib/python3.9/site-packages/airflow/utils/providers_configuration_loader.py", line 55, in wrapped_function
    return func(*args, **kwargs)
  File "/home/abresh/anaconda3/envs/airflow-environment/lib/python3.9/site-packages/airflow/cli/commands/webserver_command.py", line 484, in webserver
    run_command_with_daemon_option(
  File "/home/abresh/anaconda3/envs/airflow-environment/lib/python3.9/site-packages/airflow/cli/commands/daemon_utils.py", line 81, in run_command_with_daemon_option
    callback()
  File "/home/abresh/anaconda3/envs/airflow-environment/lib/python3.9/site-packages/airflow/cli/commands/webserver_command.py", line 487, in <lambda>
    callback=lambda: start_and_monitor_gunicorn(args),
  File "/home/abresh/anaconda3/envs/airflow-environment/lib/python3.9/site-packages/airflow/cli/commands/webserver_command.py", line 470, in start_and_monitor_gunicorn
    gunicorn_master_proc = psutil.Process(gunicorn_master_proc_pid)
  File "/home/abresh/anaconda3/envs/airflow-environment/lib/python3.9/site-packages/psutil/__init__.py", line 313, in __init__
    self._init(pid)
  File "/home/abresh/anaconda3/envs/airflow-environment/lib/python3.9/site-packages/psutil/__init__.py", line 362, in _init
    raise NoSuchProcess(pid, msg='process PID not found')
psutil.NoSuchProcess: process PID not found (pid=49796)
